Workbook

Sheet Data
I1: source : FNGuide - 기업정보 - Snapshot
A2: 기초정보
A3: 종목명 | B3: 삼성전자
A4: PER
A5: PER(Fwd.12M)
A6: 업종 PER
A7: PBR
A8: 배당수익률
A10: 시세현황 | B10: [YYYY/MM/DD] | I10: 단위 : 원, 주,%
A11: 종가
A12: 52주 최고가
A13: 52주 최저가
A14: 시가총액(상장예정포함,억원)
A15: 시가총액(보통주,억원)
A16: 발행주식수(보통주)
A17: 발행주식수(우선주)
A18: 발행주식수(보통주+우선주) | B18: =B16+B17 -> 0
A19: 52주베타
A21: 주주현황 | I21: 단위 : 주, %
A22: 자사주
A24: 투자의견 컨센서스 | B24: [YYYY/MM/DD] | I24: 단위 : 배, 원, %
A25: 투자의견
A26: 목표주가
A27: EPS
A28: PER
A29: 추정기관수
A31: 업종 비교 | I31: 단위 : 억원, 배, %
A33: 구분
A34: PER
A35: EV/EVITDA
A36: ROE
A37: 현금배당수익률
A38: 52주베타
A40: Financial Highlight | I40: 단위 : 억원, %, 배, 천주
A42: [주재무제표|연간]
B43: Annual
A45: 매출액
A46: 영업이익
A47: 영업이익(발표기준)
A48: 당기순이익
...

Sheet Q
A2: =Data!A42 -> [주재무제표|연간]
A3: =Data!A43 -> 0 | B3: Annual
B4: =Data!B44 -> 0 | C4: =Data!C44 -> 0 | D4: =Data!D44 -> 0 | E4: =Data!E44 -> 0 | F4: =Data!F44 -> 0 | G4: =Data!G44 -> 0 | H4: =Data!H44 -> 0 | I4: =Data!I44 -> 0
A5: 매출액 | B5: =Data!B45 -> 0 | C5: =Data!C45 -> 0 | D5: =Data!D45 -> 0 | E5: =Data!E45 -> 0 | F5: =Data!F45 -> 0 | G5: =Data!G45 -> 0 | H5: =Data!H45 -> 0 | I5: =Data!I45 -> 0
A6: 당기순이익 | B6: =Data!B48 -> 0 | C6: =Data!C48 -> 0 | D6: =Data!D48 -> 0 | E6: =Data!E48 -> 0 | F6: =Data!F48 -> 0 | G6: =Data!G48 -> 0 | H6: =Data!H48 -> 0 | I6: =Data!I48 -> 0
A7: 지배주주순이익 | B7: =Data!B49 -> 0 | C7: =Data!C49 -> 0 | D7: =Data!D49 -> 0 | E7: =Data!E49 -> 0 | F7: =Data!F49 -> 0 | G7: =Data!G49 -> 0 | H7: =Data!H49 -> 0 | I7: =Data!I49 -> 0
A8: 자본총계 | B8: =Data!B53 -> 0 | C8: =Data!C53 -> 0 | D8: =Data!D53 -> 0 | E8: =Data!E53 -> 0 | F8: =Data!F53 -> 0 | G8: =Data!G53 -> 0 | H8: =Data!H53 -> 0 | I8: =Data!I53 -> 0
A9: 지배주주지분 | B9: =Data!B54 -> 0 | C9: =Data!C54 -> 0 | D9: =Data!D54 -> 0 | E9: =Data!E54 -> 0 | F9: =Data!F54 -> 0 | G9: =Data!G54 -> 0 | H9: =Data!H54 -> 0 | I9: =Data!I54 -> 0
A10: ROE(%) | B10: =Data!B62 -> 0 | C10: =Data!C62 -> 0 | D10: =Data!D62 -> 0 | E10: =Data!E62 -> 0 | F10: =Data!F62 -> 0 | G10: =Data!G62 -> 0 | H10: =Data!H62 -> 0 | I10: =Data!I62 -> 0
A12: =Data!A71 -> [주재무제표|분기]
A13: =Data!A72 -> 0 | B13: Net Quarter | K13: 선택값 | M13: 4분기 평균 | O13: 계산값
B14: =Data!B73 -> 0 | C14: =Data!C73 -> 0 | D14: =Data!D73 -> 0 | E14: =Data!E73 -> 0 | F14: =Data!F73 -> 0 | G14: =Data!G73 -> 0 | H14: =Data!H73 -> 0 | I14: =Data!I73 -> 0 | O14: =MONTH(F14) -> 1 | P14: 최종월
A15: 매출액 | B15: =Data!B74 -> 0 | C15: =Data!C74 -> 0 | D15: =Data!D74 -> 0 | E15: =Data!E74 -> 0 | F15: =Data!F74 -> 0 | G15: =Data!G74 -> 0 | H15: =Data!H74 -> 0 | I15: =Data!I74 -> 0 | O15: =MIN(B15:F15,B19:F19) -> 0 | P15: 최소값(not "0")
A16: 당기순이익 | B16: =Data!B77 -> 0 | C16: =Data!C77 -> 0 | D16: =Data!D77 -> 0 | E16: =Data!E77 -> 0 | F16: =Data!F77 -> 0 | G16: =Data!G77 -> 0 | H16: =Data!H77 -> 0 | I16: =Data!I77 -> 0
A17: 지배주주순이익 | B17: =Data!B78 -> 0 | C17: =Data!C78 -> 0 | D17: =Data!D78 -> 0 | E17: =Data!E78 -> 0 | F17: =Data!F78 -> 0 | G17: =Data!G78 -> 0 | H17: =Data!H78 -> 0 | I17: =Data!I78 -> 0 | O17: =SUM(C17:F17) -> 0 | P17: 4분기 합
A18: 자본총계 | B18: =Data!B82 -> 0 | C18: =Data!C82 -> 0 | D18: =Data!D82 -> 0 | E18: =Data!E82 -> 0 | F18: =Data!F82 -> 0 | G18: =Data!G82 -> 0 | H18: =Data!H82 -> 0 | I18: =Data!I82 -> 0
A19: 지배주주지분 | B19: =Data!B83 -> 0 | C19: =Data!C83 -> 0 | D19: =Data!D83 -> 0 | E19: =Data!E83 -> 0 | F19: =Data!F83 -> 0 | G19: =Data!G83 -> 0 | H19: =Data!H83 -> 0 | I19: =Data!I83 -> 0 | O19: =AVERAGE(C19:F19) -> 0 | P19: 4분기 평균
A20: ROE(%) | B20: =Data!B91 -> 0 | C20: =Data!C91 -> 0 | D20: =Data!D91 -> 0 | E20: =Data!E91 -> 0 | F20: =Data!F91 -> 0 | G20: =Data!G91 -> 0 | H20: =Data!H91 -> 0 | I20: =Data!I91 -> 0 | K20: {=IFERROR(_xlfn.IFS(IFERROR(M20,0)<>0, M20, IFERROR(O20,0)<>0, O20, IFERROR(M28,0)<>0, M28, TRUE, O28), "분기자료부족")} -> 분기자료부족 | M20: =AVERAGEIF(C20:F20,"<>0")/100 -> #DIV/0! | O20: =IF(O15=0, O19/O15, O17/O19) -> #DIV/0! | P20: 합/평균
A22: =Data!A101 -> [별도|분기]
A23: =Data!A102 -> [IFRS 별도] | B23: Net Quarter
B24: =Data!B103 -> 0 | C24: =Data!C103 -> 0 | D24: =Data!D103 -> 0 | E24: =Data!E103 -> 0 | F24: =Data!F103 -> 0 | G24: =Data!G103 -> 0 | H24: =Data!H103 -> 0 | I24: =Data!I103 -> 0 | O24: =MONTH(F24) -> 1 | P24: 최종월
A25: 매출액 | B25: =Data!B104 -> 0 | C25: =Data!C104 -> 0 | D25: =Data!D104 -> 0 | E25: =Data!E104 -> 0 | F25: =Data!F104 -> 0 | G25: =Data!G104 -> 0 | H25: =Data!H104 -> 0 | I25: =Data!I104 -> 0 | O25: =MIN(B25:F25,B27:F27) -> 0 | P25: 최소값(not "0")
A26: 당기순이익 | B26: =Data!B107 -> 0 | C26: =Data!C107 -> 0 | D26: =Data!D107 -> 0 | E26: =Data!E107 -> 0 | F26: =Data!F107 -> 0 | G26: =Data!G107 -> 0 | H26: =Data!H107 -> 0 | I26: =Data!I107 -> 0 | O26: =SUM(C26:F26) -> 0 | P26: 4분기 합
A27: 자본총계 | B27: =Data!B110 -> 0 | C27: =Data!C110 -> 0 | D27: =Data!D110 -> 0 | E27: =Data!E110 -> 0 | F27: =Data!F110 -> 0 | G27: =Data!G110 -> 0 | H27: =Data!H110 -> 0 | I27: =Data!I110 -> 0 | O27: =AVERAGE(C27:F27) -> 0 | P27: 4분기 평균
A28: ROE(%) | B28: =Data!B117 -> 0 | C28: =Data!C117 -> 0 | D28: =Data!D117 -> 0 | E28: =Data!E117 -> 0 | F28: =Data!F117 -> 0 | G28: =Data!G117 -> 0 | H28: =Data!H117 -> 0 | I28: =Data!I117 -> 0 | M28: =AVERAGEIF(C28:F28,"<>0")/100 -> #DIV/0! | O28: =IF(O25=0, O27/O25, O26/O27) -> #DIV/0! | P28: 합/평균

Sheet S-RIM
B2: 기초자료
B3: 회사명 | C3: =Data!B3 -> 삼성전자 | D3: 보통주발행주수 | E3: =Data!B16 -> 0 | G3: 시가총액(억원) | H3: =Data!B15 -> 0
B4: 현재주가 | C4: =Data!B11 -> 0 | D4: 우선주발행주수 | E4: =Data!B17 -> 0 | G4: PER | H4: =Data!B4 -> 0
B5: 베타(β) | C5: =Data!B19 -> 0 | D5: 자기주식 | E5: =Data!B22 -> 0 | G5: 12M PER | H5: =Data!B5 -> 0 | AD5: 적용 | AE5: 1순위 | AF5: =G18 -> 0 | AH5: 초과이익 가정
AD6: 미적용 | AE6: 컨센서스 | AF6: =E18 -> 0 | AH6: 할인(할증)률
B7: 요구수익률 | F7: 투자의견 컨센서스
B8: 별도 요구수익률 | C8: 적용 | D8: 0.125 | F8: 목표주가(평균) | G8: =Data!C195 -> 0 | H8: =($C$4-G8)/G8 -> #DIV/0!
B9: 무위험이자율 | C9: 0.0425 | F9: 목표주가(최고) | G9: =MAX(Data!C196:C205) -> 0 | H9: =($C$4-G9)/G9 -> #DIV/0!
B10: 시장위험프리미엄 | C10: 0.0675 | F10: 목표주가(최저) | G10: =MIN(Data!C196:C205) -> 0 | H10: =($C$4-G10)/G10 -> #DIV/0!
B11: 최종 적용 할인율 | C11: =IF(C8="적용",D8,C9+C10*C5) -> 0.125 | F11: 52주 최고가 | G11: =Data!B12 -> 0 | H11: =($C$4-G11)/G11 -> #DIV/0!
B12: 참고링크 | C12: 채권수익률 | F12: 52주 최저가 | G12: =Data!B13 -> 0 | H12: =($C$4-G12)/G12 -> #DIV/0!
B14: ROE 추정 | C14: 1순위 | D14: =VLOOKUP(C14,AE5:AF6,2,FALSE) -> 0 | E14: =IF(I14="연도오류","연도 오류 - 서식 지우기 실행 (사용법 참조)","") -> 연도 오류 - 서식 지우기 실행 (사용법 참조) | I14: =IF(C15<2000,"연도오류","") -> 연도오류
B15: 년도 | C15: =YEAR(Data!B44) -> 1900 | D15: =YEAR(Data!C44) -> 1900 | E15: =YEAR(Data!D44) -> 1900 | F15: =YEAR(Data!E44) -> 1900 | G15: =YEAR(Data!F44) -> 1900 | H15: 최근 4분기 | I15: =IF(H16="분기자료부족",IF(F16>E16,IF(G16>F16,"상승추세",""),""),IF(F16>E16,IF(H16>F16,"상승추세",""),"")) | J15: =Q!O14 -> 1 | K15: =MONTH(Data!F44) -> 1 | L15: =MOD(J15+12-K15,12)/6 -> 0 | M15: =L15+4 -> 4 | N15: =MOD(J15+12-K15,12) -> 0
B16: ROE | C16: =Data!B62/100 -> 0 | D16: =Data!C62/100 -> 0 | E16: =Data!D62/100 -> 0 | F16: =Data!E62/100 -> 0 | G16: =Data!F62/100 -> 0 | H16: =Q!K20 -> 분기자료부족 | I16: =IF(H16="분기자료부족",IF(F16<E16,IF(G16<F16,"하락추세",""),""),IF(F16<E16,IF(H16<F16,"하락추세",""),"")) | J16: =IF(H16="분기자료부족",IF(I15="상승추세",G16,IF(I16="하락추세",G16,F18)),"") -> 0
B17: 컨센서스 | C17: =Data!G44 -> 0 | D17: =Data!H44 -> 0 | E17: =Data!I44 -> 0 | F17: 가중평균 | G17: 1순위 | H17: 별도값
B18: ROE | C18: =Data!G62/100 -> 0 | D18: =Data!H62/100 -> 0 | E18: =Data!I62/100 -> 0 | F18: =IF(H16="분기자료부족",(G16*3+F16*2+E16)/6,IF(N15=0,(G16*3+F16*2+E16)/6,(H16*3+G16*L15+F16)/M15)) -> 0 | G18: =IF(E18="컨센 없음",IF(D18="컨센 없음",IF(C18="컨센 없음",IF(H16="분기자료부족",J16,IF(I15="상승추세",H16,IF(I16="하락추세",H16,F18))),C18),D18),E18) -> 0 | H18: 0.15
B20: RIM 적정주가 | C20: 초과이익 가정 | D20: 0.2
B21: 현재주가 | C21: =C4 -> 0 | D21: 적정가 대비 | E21: 주당 가치 | F21: 주가 | G21: PER
B22: 적정주가 | C22: =IF(F25="정배열",F23,F22) -> #DIV/0! | D22: =C21/C22-1 -> #DIV/0! | E22: 초과이익 지속 | F22: =RIM계산!C11 -> #DIV/0! | G22: =RIM계산!E11 -> #DIV/0!
B23: 매도가격 | C23: =IF(C20="초과이익 가정",IF(F25="정배열",F22,F24),C22*(1+D20)) -> #DIV/0! | E23: 10%씩 감소 | F23: =RIM계산!C12 -> #DIV/0! | G23: =RIM계산!E12 -> #DIV/0!
B24: 매수가격 | C24: =IF(C20="초과이익 가정",IF(F25="정배열",F24,F22),C22*(1-D20)) -> #DIV/0! | E24: 20%씩 감소 | F24: =RIM계산!C13 -> #DIV/0! | G24: =RIM계산!E13 -> #DIV/0!
F25: =IF(F22>F24,"정배열","역배열") -> #DIV/0! | G25: =IF(F25="정배열","ROE>요구수익","ROE<요구수익") -> #DIV/0!
B27: 순이익 예측

Sheet RIM계산
A2: 최근 결산연도 | B2: =YEAR(Data!F44) -> 1900 | D2: ROE | E2: =Data!B62/100 -> 0 | F2: =Data!C62/100 -> 0 | G2: =Data!D62/100 -> 0 | H2: =Data!E62/100 -> 0 | I2: =Data!F62/100 -> 0 | J2: =Data!G62/100 -> 0 | K2: =Data!H62/100 -> 0 | L2: =Data!I62/100 -> 0 | M2: =Q!K20 -> 분기자료부족
A3: 요구수익률 | B3: ='S-RIM'!D8 -> 0.125 | D3: 지배주주지분 | E3: =Data!B54 -> 0 | F3: =Data!C54 -> 0 | G3: =Data!D54 -> 0 | H3: =Data!E54 -> 0 | I3: =Data!F54 -> 0 | J3: =Data!G54 -> 0 | K3: =Data!H54 -> 0 | L3: =Data!I54 -> 0 | M3: =IF(ISERR(Q!O9),IF(Q!K25=0,Q!F9,Q!F27),Q!F19) -> 0
A4: 발행주식수(보통+우선) | B4: =Data!B18 -> 0 | D4: 년도 | E4: =Data!B44+30 -> 30 | F4: =Data!C44+30 -> 30 | G4: =Data!D44+30 -> 30 | H4: =Data!E44+30 -> 30 | I4: =Data!F44+30 -> 30 | J4: =I4+365 -> 395 | K4: =J4+365 -> 760 | L4: =K4+365 -> 1125 | M4: =Data!F73 -> 0
A5: 자기주식 | B5: =Data!B22 -> 0 | D5: 지배주주순이익 | E5: =Data!B49 -> 0 | F5: =Data!C49 -> 0 | G5: =Data!D49 -> 0 | H5: =Data!E49 -> 0 | I5: =Data!F49 -> 0 | J5: =Data!G49 -> 0 | K5: =Data!H49 -> 0 | L5: =Data!I49 -> 0 | M5: =IF(ISERR(Q!O9),IF(Q!O25=0,Q!F7,Q!O26),Q!O17) -> 0
A7: ROE 추정 | B7: ='S-RIM'!D14 -> 0 | E7: 분석기준시점 | F7: =HLOOKUP(F8,$E$3:$M$4,2,FALSE) -> 30 | G7: 현재 | H7: =TODAY() -> 46273 | I7: 분석종료시점 | J7: =YEAR(DATE(B2+10,MONTH(F7),DAY(F7))) -> 1910
E8: 기준시점 주주지분 | F8: =IF(ISNA(HLOOKUP(B7,$E$2:$M$3,2,FALSE)),M3,HLOOKUP(B7,$E$2:$M$3,2,FALSE)) -> 0 | G8: 기준시점-현재 | H8: =F7-H7 -> -46243
A10: 초과이익 가정 | B10: 적정주주가치 | C10: 적정주가 | D10: 판단 | E10: PER
A11: 지속 | B11: =C25 -> 0 | C11: =C26 -> #DIV/0! | D11: 매도가격 | E11: =B11/$I$5 -> #DIV/0!
A12: 10%씩 감소 | B12: =C38 -> 0 | C12: =C39 -> #DIV/0! | D12: 적정가격 | E12: =B12/$I$5 -> #DIV/0!
A13: 20%씩 감소 | B13: =C51 -> 0 | C13: =C52 -> #DIV/0! | D13: 매수가격 | E13: =B13/$I$5 -> #DIV/0!
A15: 초과이익 지속계수 | B15: 1
A16: 시점 | B16: =$F$7 -> 30 | C16: =B16+365 -> 395 | D16: =C16+365 -> 760 | E16: =D16+365 -> 1125 | F16: =E16+365 -> 1490 | G16: =F16+365 -> 1855 | H16: =G16+365 -> 2220 | I16: =H16+365 -> 2585 | J16: =I16+365 -> 2950 | ... L16: =K16+365 -> 3680
A17: 요구수익률 | B17: =$B$3 -> 0.125 | C17: =B17 -> 0.125 | D17: =C17 -> 0.125 | E17: =D17 -> 0.125 | F17: =E17 -> 0.125 | G17: =F17 -> 0.125 | H17: =G17 -> 0.125 | I17: =H17 -> 0.125 | J17: =I17 -> 0.125 | ... L17: =K17 -> 0.125
A18: 초과이익률 | B18: =$B$7-B17 -> -0.125 | C18: =IF(YEAR(C16)>$J$7,0,B18*$B$15) -> -0.125 | D18: =IF(YEAR(D16)>$J$7,0,C18*$B$15) -> -0.125 | E18: =IF(YEAR(E16)>$J$7,0,D18*$B$15) -> -0.125 | F18: =IF(YEAR(F16)>$J$7,0,E18*$B$15) -> -0.125 | G18: =IF(YEAR(G16)>$J$7,0,F18*$B$15) -> -0.125 | H18: =IF(YEAR(H16)>$J$7,0,G18*$B$15) -> -0.125 | I18: =IF(YEAR(I16)>$J$7,0,H18*$B$15) -> -0.125 | J18: =IF(YEAR(J16)>$J$7,0,I18*$B$15) -> -0.125 | ... L18: =IF(YEAR(L16)>$J$7,0,K18*$B$15) -> -0.125
A19: ROE | B19: =B17+B18 -> 0 | C19: =C17+C18 -> 0 | D19: =D17+D18 -> 0 | E19: =E17+E18 -> 0 | F19: =F17+F18 -> 0 | G19: =G17+G18 -> 0 | H19: =H17+H18 -> 0 | I19: =I17+I18 -> 0 | ... L19: =L17+L18 -> 0
A20: 지배주주순이익 | C20: =B21*C19 -> 0 | D20: =C21*D19 -> 0 | E20: =D21*E19 -> 0 | F20: =E21*F19 -> 0 | G20: =F21*G19 -> 0 | H20: =G21*H19 -> 0 | I20: =H21*I19 -> 0 | J20: =I21*J19 -> 0 | ... L20: =K21*L19 -> 0
A21: 지배주주지분 | B21: =$F$8 -> 0 | C21: =B21+C20 -> 0 | D21: =C21+D20 -> 0 | E21: =D21+E20 -> 0 | F21: =E21+F20 -> 0 | G21: =F21+G20 -> 0 | H21: =G21+H20 -> 0 | I21: =H21+I20 -> 0 | J21: =I21+J20 -> 0 | ... L21: =K21+L20 -> 0
A22: 초과이익 | C22: =C20-B21*C17 -> 0 | D22: =D20-C21*D17 -> 0 | E22: =E20-D21*E17 -> 0 | F22: =F20-E21*F17 -> 0 | G22: =G20-F21*G17 -> 0 | H22: =H20-G21*H17 -> 0 | I22: =I20-H21*I17 -> 0 | J22: =J20-I21*J17 -> 0 | ... L22: =L20-K21*L17 -> 0
A23: PV of RI | B23: =NPV($B$3,C22:L22) -> 0
B24: 분석시점 기준 | C24: 현재 기준
A25: RIM 주주가치 | B25: =B21+B23 -> 0 | C25: =B25/(1+$B$3)^($H$8/365) -> 0
A26: RIM 적정주가 | B26: =B25*100000000/($B$4-$B$5) -> #DIV/0! | C26: =B26/(1+$B$3)^($H$8/365) -> #DIV/0!
A28: 초과이익 지속계수 | B28: 0.9
A29: 시점 | B29: =$F$7 -> 30 | C29: =B29+365 -> 395 | D29: =C29+365 -> 760 | E29: =D29+365 -> 1125 | F29: =E29+365 -> 1490 | G29: =F29+365 -> 1855 | H29: =G29+365 -> 2220 | I29: =H29+365 -> 2585 | J29: =I29+365 -> 2950 | ... L29: =K29+365 -> 3680
A30: 요구수익률 | B30: =$B$3 -> 0.125 | C30: =B30 -> 0.125 | D30: =C30 -> 0.125 | E30: =D30 -> 0.125 | F30: =E30 -> 0.125 | G30: =F30 -> 0.125 | H30: =G30 -> 0.125 | I30: =H30 -> 0.125 | J30: =I30 -> 0.125 | ... L30: =K30 -> 0.125
A31: 초과이익률 | B31: =$B$7-B30 -> -0.125 | C31: =IF(YEAR(C16)>$J$7,0,B31*$B$28) -> -0.1125 | D31: =IF(YEAR(D16)>$J$7,0,C31*$B$28) -> -0.10125 | E31: =IF(YEAR(E16)>$J$7,0,D31*$B$28) -> -0.091125 | F31: =IF(YEAR(F16)>$J$7,0,E31*$B$28) -> -0.0820125 | G31: =IF(YEAR(G16)>$J$7,0,F31*$B$28) -> -0.07381125 | H31: =IF(YEAR(H16)>$J$7,0,G31*$B$28) -> -0.066430125 | I31: =IF(YEAR(I16)>$J$7,0,H31*$B$28) -> -0.059787113 | J31: =IF(YEAR(J16)>$J$7,0,I31*$B$28) -> -0.053808401 | ... L31: =IF(YEAR(L16)>$J$7,0,K31*$B$28) -> -0.043584805
A32: ROE | B32: =B30+B31 -> 0 | C32: =C30+C31 -> 0.0125 | D32: =D30+D31 -> 0.02375 | E32: =E30+E31 -> 0.033875 | F32: =F30+F31 -> 0.0429875 | G32: =G30+G31 -> 0.05118875 | H32: =H30+H31 -> 0.058569875 | I32: =I30+I31 -> 0.065212887 | ... L32: =L30+L31 -> 0.081415195
A33: 지배주주순이익 | C33: =B34*C32 -> 0 | D33: =C34*D32 -> 0 | E33: =D34*E32 -> 0 | F33: =E34*F32 -> 0 | G33: =F34*G32 -> 0 | H33: =G34*H32 -> 0 | I33: =H34*I32 -> 0 | J33: =I34*J32 -> 0 | ... L33: =K34*L32 -> 0
A34: 지배주주지분 | B34: =$F$8 -> 0 | C34: =B34+C33 -> 0 | D34: =C34+D33 -> 0 | E34: =D34+E33 -> 0 | F34: =E34+F33 -> 0 | G34: =F34+G33 -> 0 | H34: =G34+H33 -> 0 | I34: =H34+I33 -> 0 | J34: =I34+J33 -> 0 | ... L34: =K34+L33 -> 0
A35: 초과이익 | C35: =C33-B34*C30 -> 0 | D35: =D33-C34*D30 -> 0 | E35: =E33-D34*E30 -> 0 | F35: =F33-E34*F30 -> 0 | G35: =G33-F34*G30 -> 0 | H35: =H33-G34*H30 -> 0 | I35: =I33-H34*I30 -> 0 | J35: =J33-I34*J30 -> 0 | ... L35: =L33-K34*L30 -> 0
A36: PV of RI | B36: =NPV($B$3,C35:L35) -> 0
B37: 분석시점 기준 | C37: 현재 기준
A38: RIM 주주가치 | B38: =B34+B36 -> 0 | C38: =B38/(1+$B$3)^($H$8/365) -> 0
A39: RIM 적정주가 | B39: =B38*100000000/($B$4-$B$5) -> #DIV/0! | C39: =B39/(1+$B$3)^($H$8/365) -> #DIV/0!
A41: 초과이익 지속계수 | B41: 0.8
A42: 시점 | B42: =$F$7 -> 30 | C42: =B42+365 -> 395 | D42: =C42+365 -> 760 | E42: =D42+365 -> 1125 | F42: =E42+365 -> 1490 | G42: =F42+365 -> 1855 | H42: =G42+365 -> 2220 | I42: =H42+365 -> 2585 | J42: =I42+365 -> 2950 | ... L42: =K42+365 -> 3680
A43: 요구수익률 | B43: =$B$3 -> 0.125 | C43: =B43 -> 0.125 | D43: =C43 -> 0.125 | E43: =D43 -> 0.125 | F43: =E43 -> 0.125 | G43: =F43 -> 0.125 | H43: =G43 -> 0.125 | I43: =H43 -> 0.125 | J43: =I43 -> 0.125 | ... L43: =K43 -> 0.125
A44: 초과이익률 | B44: =$B$7-B43 -> -0.125 | C44: =IF(YEAR(C16)>$J$7,0,B44*$B$41) -> -0.1 | D44: =IF(YEAR(D16)>$J$7,0,C44*$B$41) -> -0.08 | E44: =IF(YEAR(E16)>$J$7,0,D44*$B$41) -> -0.064 | F44: =IF(YEAR(F16)>$J$7,0,E44*$B$41) -> -0.0512 | G44: =IF(YEAR(G16)>$J$7,0,F44*$B$41) -> -0.04096 | H44: =IF(YEAR(H16)>$J$7,0,G44*$B$41) -> -0.032768 | I44: =IF(YEAR(I16)>$J$7,0,H44*$B$41) -> -0.0262144 | J44: =IF(YEAR(J16)>$J$7,0,I44*$B$41) -> -0.02097152 | ... L44: =IF(YEAR(L16)>$J$7,0,K44*$B$41) -> -0.013421773
A45: ROE | B45: =B43+B44 -> 0 | C45: =C43+C44 -> 0.025 | D45: =D43+D44 -> 0.045 | E45: =E43+E44 -> 0.061 | F45: =F43+F44 -> 0.0738 | G45: =G43+G44 -> 0.08404 | H45: =H43+H44 -> 0.092232 | I45: =I43+I44 -> 0.0987856 | ... L45: =L43+L44 -> 0.11157823
A46: 지배주주순이익 | C46: =B47*C45 -> 0 | D46: =C47*D45 -> 0 | E46: =D47*E45 -> 0 | F46: =E47*F45 -> 0 | G46: =F47*G45 -> 0 | H46: =G47*H45 -> 0 | I46: =H47*I45 -> 0 | J46: =I47*J45 -> 0 | ... L46: =K47*L45 -> 0
...
